<!-- ToDo - verify the torque control input -->
<mujoco model="hopper">
	<compiler angle="degree" inertiafromgeom="true" />
	<default>
		<joint armature="1" damping="1" limited="true" />
		<geom conaffinity="1" condim="1" contype="1" margin="0.001" material="geom" rgba="0.8 0.6 .4 1" solimp=".8 .8 .01" solref=".02 1" />
		<motor ctrllimited="true" ctrlrange="-.4 .4" />
	</default>
	<option integrator="RK4" timestep="0.006" />
	<visual>
		<map znear="0.02" />
	</visual>
	<worldbody>
		<light cutoff="100" diffuse="1 1 1" dir="-0 0 -1.3" directional="true" exponent="1" pos="0 0 1.3" specular=".1 .1 .1" />
		<geom conaffinity="1" condim="3" name="floor" pos="0 0 0" rgba="0.8 0.9 0.8 1" size="20 20 .125" type="plane" material="MatPlane" />
		<!-- Anchor Point -->
		<body name="anchor_point" pos="0 0 1">
			<joint name="thigh_hinge" type="hinge" pos="0 0 0" axis="0 1 0" range="-90 90" damping="0.1" />
			<!-- Thigh -->
			<body name="thigh" pos="0 0 -0.04795">
				<!-- Thigh definition -->
				<geom friction="0.9" name="thigh_geom" size="0.040 0.04795" mass="0.9372" type="capsule" />
				<inertial mass="0.9372" pos="0.00673 -0.00218 0.02905" diaginertia="0.001723 0.002207 0.002326" />
				<site name="force_site_x" pos="0 0 0.04795" size="0.01" type="sphere" rgba="0.7 0.2 0.9 0.5" />
				<!-- Thigh IMU Definition -->
				<site name="thigh_imu" pos="0 0 0.006049999999999997" size="0.01" type="sphere" rgba="0.3 0.2 0.2 0.5" />
				<!-- Knee Definition -->
				<body name="knee" pos="0 0 -0.04795">
					<joint axis="0 -1 0" name="knee_joint" pos="0 0 0" range="-95 0" type="hinge" />
					<!-- Shank definition - note the value is half the length -->
					<geom friction="0.9" pos="0 0 -0.1755" mass="3.171" name="leg_geom" size="0.040 0.1755" type="capsule" />
					<inertial mass="3.171" pos="-0.00719 0.00339 -0.1706" diaginertia="0.00607 0.02592 0.02626" />
					<!-- Foot Definition (Shank length used here for placement) -->
					<body name="foot" pos="0.1 0 -0.351" quat="0.70710678118654757 0 -0.70710678118654746 0">
						<joint axis="0 -1 0" name="foot_joint" pos="0 0 0.085" range="-40 40" type="hinge" />
						<geom friction="0.9" pos="-0.0475 0 0" mass="0.7453112309" name="foot_geom" size="0.0475 0.15" type="capsule" />
						<inertial mass="0.7453112309" pos="0.02751 -0.00002 -0.40911" diaginertia="0.0003585 0.0024096 0.0024149" />
						<!-- Load Cell -->
						<site name="foot_load_sensor" pos="-0.025 0 0.085" size="0.01" type="sphere" rgba="0 0.5 0 0.5" />
						<!-- Foot IMU -->
						<site name="foot_imu" pos="-0.025 0 -0.0049999999999999906" size="0.01" type="sphere" rgba="0 1 1 0.5" />
					</body>
				</body>
			</body>
		</body>
	</worldbody>
	<actuator>
		<!-- Check the torque value -->
		<!-- Can be used to control knee and foot joint with torque if needed -->
		<!-- <general joint="thigh_hinge" name="thigh_torque" ctrllimited="true" ctrlrange="-1.0 1.0" gainprm="20" biastype="none" /> -->
		<motor ctrllimited="true" name="thigh_torque" ctrlrange="-1.0 1.0" gear="50" joint="thigh_hinge" />
	</actuator>
	<sensor>
		<force name="load_sensor" site="foot_load_sensor" />
		<gyro name="foot_gyro_sensor" site="foot_imu" />
		<accelerometer name="foot_accel_sensor" site="foot_imu" />
		<gyro name="thigh_gyro_sensor" site="thigh_imu" />
		<accelerometer name="thigh_accel_sensor" site="thigh_imu" />
		<force site="force_site_x" name="sensor_x_force" />
	</sensor>
	<asset>
		<texture type="skybox" builtin="gradient" rgb1=".4 .6 .8" rgb2="0 0 0" width="100" height="100" markrgb="1 1 1" />
		<texture builtin="flat" height="1278" mark="cross" markrgb="1 1 1" name="texgeom" random="0.01" rgb1="0.8 0.6 0.4" rgb2="0.8 0.6 0.4" type="cube" width="127" />
		<texture builtin="checker" height="100" name="texplane" rgb1=".1 .2 .3" rgb2=".2 .3 .4" type="2d" width="100" />
		<material name="MatPlane" reflectance="0.2" shininess="1" specular="1" texrepeat="60 60" texture="texplane" />
		<material name="geom" texture="texgeom" texuniform="true" />
	</asset>
</mujoco>
